Workbook

Sheet CONFIGURACION
A1: CONFIGURACIÓN Y GUÍA DE USO
A4: Año de planificación | B4: 2026
A5: Mes de planificación | B5: 10
A6: Primer día del mes | B6: =DATE(B4,B5,1) -> 46296
A7: Último día del mes | B7: =EOMONTH(B6,0) -> 46326
A8: Fecha de consulta | B8: =TODAY() -> 46309
A10: INSTRUCCIONES
A11: 1. Cambie año y mes en B4 y B5; calendario y entregas se actualizan.
A12: 2. Edite las fechas y responsables en ACTIVIDADES (amarillo = dato por completar).
A13: 3. En ACTIVIDADES actualice Estado, avance y fecha real de entrega.
A14: 4. Agregue actividades extraordinarias en las filas libres de ACTIVIDADES.
A15: 5. El calendario y la EDT usan el mismo código de actividad.
A16: 6. Las fechas que cruzan fin de mes requieren confirmar el mes de entrega.

Sheet PROYECTOS
A1: CARTERA DE PROYECTOS ACTIVOS
A4: Proyecto | B4: Estado | C4: Supervisor principal | D4: Supervisor de apoyo | E4: Observaciones | F4: Última actualización
A5: CDJ GUAYAQUIL | B5: Activo | C5: EDDY VELEZ | E5: Asignación editable
A6: CDJ CANTONES | B6: Activo | C6: LUIS HARO | E6: Asignación editable
A7: HOSP. MERCED | B7: Activo | C7: LUIS HARO | E7: Asignación editable
A8: SECAP | B8: Activo | C8: EDDY VELEZ | E8: Asignación editable
A9: SENAE | B9: Activo | C9: EDDY VELEZ | E9: Asignación editable
A10: CELEC - ORIENTE | B10: Activo | C10: EDDY VELEZ | E10: Asignación editable
A11: CELEC - GUAYAQUIL | B11: Activo | C11: EDDY VELEZ | E11: Asignación editable
A12: MSP | B12: Activo | C12: EDDY VELEZ | E12: Asignación editable

Sheet ACTIVIDADES
A1: PLAN MAESTRO DE ACTIVIDADES | EDITABLE
A4: Código EDT | B4: Proyecto | C4: Tipo | D4: Actividad / entregable | E4: Responsable | F4: Día inicio | G4: Día límite | H4: Inicio planificado | I4: Entrega límite | J4: Fecha entrega real | K4: Estado | L4: Prioridad | M4: Avance % | N4: Días restantes | O4: Semáforo | P4: Observaciones | Q4: Fuente / referencia
A5: 01.01 | B5: CDJ GUAYAQUIL | C5: Informe | D5: Solicitar y entregar informe mensual | E5: LUIS HARO | F5: 29 | G5: 3 | H5: 46302 | I5: 46305 | K5: Pendiente | L5: Alta | M5: 0 | N5: =IF(I5="","",I5-CONFIGURACION!$B$8) -> -4 | O5: =IF(I5="","Sin fecha",IF(K5="Cerrado","Completado",IF(I5<CONFIGURACION!$B$8,"Vencido",IF(I5-CONFIGURACION!$B$8<=3,"Próximo","En plazo")))) -> Vencido | P5: Fechas del cronograma de informes de agosto 2026 | Q5: Imagen: cronograma de informes
A6: 01.02 | B6: CDJ GUAYAQUIL | C6: Abastecimiento | D6: Solicitar requerimientos de insumos | E6: EDDY VELEZ | F6: 7 | G6: 10 | H6: 46294 | I6: 46298 | J6: 46296 | K6: Cerrado | L6: Alta | M6: 1 | N6: =IF(I6="","",I6-CONFIGURACION!$B$8) -> -11 | O6: =IF(I6="","Sin fecha",IF(K6="Cerrado","Completado",IF(I6<CONFIGURACION!$B$8,"Vencido",IF(I6-CONFIGURACION!$B$8<=3,"Próximo","En plazo")))) -> Completado | P6: Fechas del cronograma de abastecimiento de septiembre 2026 | Q6: Imagen: cronograma abastecimiento
A7: 01.03 | B7: CDJ GUAYAQUIL | C7: Corte | D7: Preparar y entregar corte del día 5 | F7: 5 | G7: 5 | H7: =IF(F7="","",DATE(CONFIGURACION!$B$4,CONFIGURACION!$B$5,MIN(F7,DAY(CONFIGURACION!$B$7)))) -> 46300 | I7: =IF(G7="","",DATE(CONFIGURACION!$B$4,CONFIGURACION!$B$5,MIN(G7,DAY(CONFIGURACION!$B$7)))) -> 46300 | K7: Cerrado | L7: Alta | M7: 1 | N7: =IF(I7="","",I7-CONFIGURACION!$B$8) -> -9 | O7: =IF(I7="","Sin fecha",IF(K7="Cerrado","Completado",IF(I7<CONFIGURACION!$B$8,"Vencido",IF(I7-CONFIGURACION!$B$8<=3,"Próximo","En plazo")))) -> Completado | P7: Corte fijo mensual; confirmar responsable | Q7: Indicaciones de coordinación
A8: 01.04 | B8: CDJ GUAYAQUIL | C8: Corte | D8: Preparar y entregar corte del día 10 | F8: 10 | G8: 10 | H8: =IF(F8="","",DATE(CONFIGURACION!$B$4,CONFIGURACION!$B$5,MIN(F8,DAY(CONFIGURACION!$B$7)))) -> 46305 | I8: =IF(G8="","",DATE(CONFIGURACION!$B$4,CONFIGURACION!$B$5,MIN(G8,DAY(CONFIGURACION!$B$7)))) -> 46305 | K8: Cerrado | L8: Alta | M8: 1 | N8: =IF(I8="","",I8-CONFIGURACION!$B$8) -> -4 | O8: =IF(I8="","Sin fecha",IF(K8="Cerrado","Completado",IF(I8<CONFIGURACION!$B$8,"Vencido",IF(I8-CONFIGURACION!$B$8<=3,"Próximo","En plazo")))) -> Completado | P8: Corte fijo mensual; confirmar responsable | Q8: Indicaciones de coordinación
A9: 01.05 | B9: CDJ GUAYAQUIL | C9: Corte | D9: Preparar y entregar corte del día 20 | F9: 20 | G9: 20 | H9: =IF(F9="","",DATE(CONFIGURACION!$B$4,CONFIGURACION!$B$5,MIN(F9,DAY(CONFIGURACION!$B$7)))) -> 46315 | I9: =IF(G9="","",DATE(CONFIGURACION!$B$4,CONFIGURACION!$B$5,MIN(G9,DAY(CONFIGURACION!$B$7)))) -> 46315 | K9: Pendiente | L9: Alta | M9: 0 | N9: =IF(I9="","",I9-CONFIGURACION!$B$8) -> 6 | O9: =IF(I9="","Sin fecha",IF(K9="Cerrado","Completado",IF(I9<CONFIGURACION!$B$8,"Vencido",IF(I9-CONFIGURACION!$B$8<=3,"Próximo","En plazo")))) -> En plazo | P9: Corte fijo mensual; confirmar responsable | Q9: Indicaciones de coordinación
A10: 01.06 | B10: CDJ GUAYAQUIL | C10: Corte | D10: Preparar y entregar corte del día 26 | F10: 26 | G10: 26 | H10: =IF(F10="","",DATE(CONFIGURACION!$B$4,CONFIGURACION!$B$5,MIN(F10,DAY(CONFIGURACION!$B$7)))) -> 46321 | I10: =IF(G10="","",DATE(CONFIGURACION!$B$4,CONFIGURACION!$B$5,MIN(G10,DAY(CONFIGURACION!$B$7)))) -> 46321 | K10: Pendiente | L10: Alta | M10: 0 | N10: =IF(I10="","",I10-CONFIGURACION!$B$8) -> 12 | O10: =IF(I10="","Sin fecha",IF(K10="Cerrado","Completado",IF(I10<CONFIGURACION!$B$8,"Vencido",IF(I10-CONFIGURACION!$B$8<=3,"Próximo","En plazo")))) -> En plazo | P10: Corte fijo mensual; confirmar responsable | Q10: Indicaciones de coordinación
A11: 01.07 | B11: CDJ GUAYAQUIL | C11: Corte | D11: Preparar y entregar corte del día 30 | F11: 30 | G11: 30 | H11: =IF(F11="","",DATE(CONFIGURACION!$B$4,CONFIGURACION!$B$5,MIN(F11,DAY(CONFIGURACION!$B$7)))) -> 46325 | I11: =IF(G11="","",DATE(CONFIGURACION!$B$4,CONFIGURACION!$B$5,MIN(G11,DAY(CONFIGURACION!$B$7)))) -> 46325 | K11: Pendiente | L11: Alta | M11: 0 | N11: =IF(I11="","",I11-CONFIGURACION!$B$8) -> 16 | O11: =IF(I11="","Sin fecha",IF(K11="Cerrado","Completado",IF(I11<CONFIGURACION!$B$8,"Vencido",IF(I11-CONFIGURACION!$B$8<=3,"Próximo","En plazo")))) -> En plazo | P11: Corte fijo mensual; confirmar responsable | Q11: Indicaciones de coordinación
A12: 02.01 | B12: CDJ CANTONES | C12: Informe | D12: Solicitar y entregar informe mensual | E12: LUIS HARO | F12: 29 | G12: 3 | H12: 46302 | I12: 46305 | J12: 46309 | K12: Cerrado | L12: Alta | M12: 1 | N12: =IF(I12="","",I12-CONFIGURACION!$B$8) -> -4 | O12: =IF(I12="","Sin fecha",IF(K12="Cerrado","Completado",IF(I12<CONFIGURACION!$B$8,"Vencido",IF(I12-CONFIGURACION!$B$8<=3,"Próximo","En plazo")))) -> Completado | P12: Fechas del cronograma de informes de agosto 2026 | Q12: Imagen: cronograma de informes
A13: 02.02 | B13: CDJ CANTONES | C13: Abastecimiento | D13: Solicitar requerimientos de insumos | E13: LUIS HARO | F13: 7 | G13: 10 | H13: 46324 | I13: 46329 | K13: Pendiente | L13: Alta | M13: 0 | N13: =IF(I13="","",I13-CONFIGURACION!$B$8) -> 20 | O13: =IF(I13="","Sin fecha",IF(K13="Cerrado","Completado",IF(I13<CONFIGURACION!$B$8,"Vencido",IF(I13-CONFIGURACION!$B$8<=3,"Próximo","En plazo")))) -> En plazo | P13: Fechas del cronograma de abastecimiento de septiembre 2026 | Q13: Imagen: cronograma abastecimiento
A14: 02.03 | B14: CDJ CANTONES | C14: Corte | D14: Preparar y entregar corte del día 5 | F14: 5 | G14: 5 | H14: =IF(F14="","",DATE(CONFIGURACION!$B$4,CONFIGURACION!$B$5,MIN(F14,DAY(CONFIGURACION!$B$7)))) -> 46300 | I14: =IF(G14="","",DATE(CONFIGURACION!$B$4,CONFIGURACION!$B$5,MIN(G14,DAY(CONFIGURACION!$B$7)))) -> 46300 | K14: Cerrado | L14: Alta | M14: 1 | N14: =IF(I14="","",I14-CONFIGURACION!$B$8) -> -9 | O14: =IF(I14="","Sin fecha",IF(K14="Cerrado","Completado",IF(I14<CONFIGURACION!$B$8,"Vencido",IF(I14-CONFIGURACION!$B$8<=3,"Próximo","En plazo")))) -> Completado | P14: Corte fijo mensual; confirmar responsable | Q14: Indicaciones de coordinación
A15: 02.04 | B15: CDJ CANTONES | C15: Corte | D15: Preparar y entregar corte del día 10 | F15: 10 | G15: 10 | H15: =IF(F15="","",DATE(CONFIGURACION!$B$4,CONFIGURACION!$B$5,MIN(F15,DAY(CONFIGURACION!$B$7)))) -> 46305 | I15: =IF(G15="","",DATE(CONFIGURACION!$B$4,CONFIGURACION!$B$5,MIN(G15,DAY(CONFIGURACION!$B$7)))) -> 46305 | K15: Cerrado | L15: Alta | M15: 1 | N15: =IF(I15="","",I15-CONFIGURACION!$B$8) -> -4 | O15: =IF(I15="","Sin fecha",IF(K15="Cerrado","Completado",IF(I15<CONFIGURACION!$B$8,"Vencido",IF(I15-CONFIGURACION!$B$8<=3,"Próximo","En plazo")))) -> Completado | P15: Corte fijo mensual; confirmar responsable | Q15: Indicaciones de coordinación
A16: 02.05 | B16: CDJ CANTONES | C16: Corte | D16: Preparar y entregar corte del día 20 | F16: 20 | G16: 20 | H16: =IF(F16="","",DATE(CONFIGURACION!$B$4,CONFIGURACION!$B$5,MIN(F16,DAY(CONFIGURACION!$B$7)))) -> 46315 | I16: =IF(G16="","",DATE(CONFIGURACION!$B$4,CONFIGURACION!$B$5,MIN(G16,DAY(CONFIGURACION!$B$7)))) -> 46315 | K16: Pendiente | L16: Alta | M16: 0 | N16: =IF(I16="","",I16-CONFIGURACION!$B$8) -> 6 | O16: =IF(I16="","Sin fecha",IF(K16="Cerrado","Completado",IF(I16<CONFIGURACION!$B$8,"Vencido",IF(I16-CONFIGURACION!$B$8<=3,"Próximo","En plazo")))) -> En plazo | P16: Corte fijo mensual; confirmar responsable | Q16: Indicaciones de coordinación
A17: 02.06 | B17: CDJ CANTONES | C17: Corte | D17: Preparar y entregar corte del día 26 | F17: 26 | G17: 26 | H17: =IF(F17="","",DATE(CONFIGURACION!$B$4,CONFIGURACION!$B$5,MIN(F17,DAY(CONFIGURACION!$B$7)))) -> 46321 | I17: =IF(G17="","",DATE(CONFIGURACION!$B$4,CONFIGURACION!$B$5,MIN(G17,DAY(CONFIGURACION!$B$7)))) -> 46321 | K17: Pendiente | L17: Alta | M17: 0 | N17: =IF(I17="","",I17-CONFIGURACION!$B$8) -> 12 | O17: =IF(I17="","Sin fecha",IF(K17="Cerrado","Completado",IF(I17<CONFIGURACION!$B$8,"Vencido",IF(I17-CONFIGURACION!$B$8<=3,"Próximo","En plazo")))) -> En plazo | P17: Corte fijo mensual; confirmar responsable | Q17: Indicaciones de coordinación
A18: 02.07 | B18: CDJ CANTONES | C18: Corte | D18: Preparar y entregar corte del día 30 | F18: 30 | G18: 30 | H18: =IF(F18="","",DATE(CONFIGURACION!$B$4,CONFIGURACION!$B$5,MIN(F18,DAY(CONFIGURACION!$B$7)))) -> 46325 | I18: =IF(G18="","",DATE(CONFIGURACION!$B$4,CONFIGURACION!$B$5,MIN(G18,DAY(CONFIGURACION!$B$7)))) -> 46325 | K18: Pendiente | L18: Alta | M18: 0 | N18: =IF(I18="","",I18-CONFIGURACION!$B$8) -> 16 | O18: =IF(I18="","Sin fecha",IF(K18="Cerrado","Completado",IF(I18<CONFIGURACION!$B$8,"Vencido",IF(I18-CONFIGURACION!$B$8<=3,"Próximo","En plazo")))) -> En plazo | P18: Corte fijo mensual; confirmar responsable | Q18: Indicaciones de coordinación
A19: 03.01 | B19: HOSP. MERCED | C19: Informe | D19: Solicitar y entregar informe mensual | E19: LUIS HARO | F19: 18 | G19: 23 | H19: 46297 | I19: 46300 | J19: 46300 | K19: Cerrado | L19: Alta | M19: 1 | N19: =IF(I19="","",I19-CONFIGURACION!$B$8) -> -9 | O19: =IF(I19="","Sin fecha",IF(K19="Cerrado","Completado",IF(I19<CONFIGURACION!$B$8,"Vencido",IF(I19-CONFIGURACION!$B$8<=3,"Próximo","En plazo")))) -> Completado | P19: Fechas del cronograma de informes de agosto 2026 | Q19: Imagen: cronograma de informes
A20: 03.02 | B20: HOSP. MERCED | C20: Abastecimiento | D20: Solicitar requerimientos de insumos | E20: LUIS HARO | F20: 2 | G20: 5 | H20: 46313 | I20: 46318 | K20: Pendiente | L20: Alta | M20: 0 | N20: =IF(I20="","",I20-CONFIGURACION!$B$8) -> 9 | O20: =IF(I20="","Sin fecha",IF(K20="Cerrado","Completado",IF(I20<CONFIGURACION!$B$8,"Vencido",IF(I20-CONFIGURACION!$B$8<=3,"Próximo","En plazo")))) -> En plazo | P20: Fechas del cronograma de abastecimiento de septiembre 2026 | Q20: Imagen: cronograma abastecimiento
A21: 03.03 | B21: HOSP. MERCED | C21: Corte | D21: Preparar y entregar corte del día 5 | F21: 5 | G21: 5 | H21: =IF(F21="","",DATE(CONFIGURACION!$B$4,CONFIGURACION!$B$5,MIN(F21,DAY(CONFIGURACION!$B$7)))) -> 46300 | I21: =IF(G21="","",DATE(CONFIGURACION!$B$4,CONFIGURACION!$B$5,MIN(G21,DAY(CONFIGURACION!$B$7)))) -> 46300 | K21: Cerrado | L21: Alta | M21: 1 | N21: =IF(I21="","",I21-CONFIGURACION!$B$8) -> -9 | O21: =IF(I21="","Sin fecha",IF(K21="Cerrado","Completado",IF(I21<CONFIGURACION!$B$8,"Vencido",IF(I21-CONFIGURACION!$B$8<=3,"Próximo","En plazo")))) -> Completado | P21: Corte fijo mensual; confirmar responsable | Q21: Indicaciones de coordinación
A22: 03.04 | B22: HOSP. MERCED | C22: Corte | D22: Preparar y entregar corte del día 10 | F22: 10 | G22: 10 | H22: =IF(F22="","",DATE(CONFIGURACION!$B$4,CONFIGURACION!$B$5,MIN(F22,DAY(CONFIGURACION!$B$7)))) -> 46305 | I22: =IF(G22="","",DATE(CONFIGURACION!$B$4,CONFIGURACION!$B$5,MIN(G22,DAY(CONFIGURACION!$B$7)))) -> 46305 | K22: Cerrado | L22: Alta | M22: 1 | N22: =IF(I22="","",I22-CONFIGURACION!$B$8) -> -4 | O22: =IF(I22="","Sin fecha",IF(K22="Cerrado","Completado",IF(I22<CONFIGURACION!$B$8,"Vencido",IF(I22-CONFIGURACION!$B$8<=3,"Próximo","En plazo")))) -> Completado | P22: Corte fijo mensual; confirmar responsable | Q22: Indicaciones de coordinación
A23: 03.05 | B23: HOSP. MERCED | C23: Corte | D23: Preparar y entregar corte del día 20 | F23: 20 | G23: 20 | H23: =IF(F23="","",DATE(CONFIGURACION!$B$4,CONFIGURACION!$B$5,MIN(F23,DAY(CONFIGURACION!$B$7)))) -> 46315 | I23: =IF(G23="","",DATE(CONFIGURACION!$B$4,CONFIGURACION!$B$5,MIN(G23,DAY(CONFIGURACION!$B$7)))) -> 46315 | K23: Pendiente | L23: Alta | M23: 0 | N23: =IF(I23="","",I23-CONFIGURACION!$B$8) -> 6 | O23: =IF(I23="","Sin fecha",IF(K23="Cerrado","Completado",IF(I23<CONFIGURACION!$B$8,"Vencido",IF(I23-CONFIGURACION!$B$8<=3,"Próximo","En plazo")))) -> En plazo | P23: Corte fijo mensual; confirmar responsable | Q23: Indicaciones de coordinación
A24: 03.06 | B24: HOSP. MERCED | C24: Corte | D24: Preparar y entregar corte del día 26 | F24: 26 | G24: 26 | H24: =IF(F24="","",DATE(CONFIGURACION!$B$4,CONFIGURACION!$B$5,MIN(F24,DAY(CONFIGURACION!$B$7)))) -> 46321 | I24: =IF(G24="","",DATE(CONFIGURACION!$B$4,CONFIGURACION!$B$5,MIN(G24,DAY(CONFIGURACION!$B$7)))) -> 46321 | K24: Pendiente | L24: Alta | M24: 0 | N24: =IF(I24="","",I24-CONFIGURACION!$B$8) -> 12 | O24: =IF(I24="","Sin fecha",IF(K24="Cerrado","Completado",IF(I24<CONFIGURACION!$B$8,"Vencido",IF(I24-CONFIGURACION!$B$8<=3,"Próximo","En plazo")))) -> En plazo | P24: Corte fijo mensual; confirmar responsable | Q24: Indicaciones de coordinación
A25: 03.07 | B25: HOSP. MERCED | C25: Corte | D25: Preparar y entregar corte del día 30 | F25: 30 | G25: 30 | H25: =IF(F25="","",DATE(CONFIGURACION!$B$4,CONFIGURACION!$B$5,MIN(F25,DAY(CONFIGURACION!$B$7)))) -> 46325 | I25: =IF(G25="","",DATE(CONFIGURACION!$B$4,CONFIGURACION!$B$5,MIN(G25,DAY(CONFIGURACION!$B$7)))) -> 46325 | K25: Pendiente | L25: Alta | M25: 0 | N25: =IF(I25="","",I25-CONFIGURACION!$B$8) -> 16 | O25: =IF(I25="","Sin fecha",IF(K25="Cerrado","Completado",IF(I25<CONFIGURACION!$B$8,"Vencido",IF(I25-CONFIGURACION!$B$8<=3,"Próximo","En plazo")))) -> En plazo | P25: Corte fijo mensual; confirmar responsable | Q25: Indicaciones de coordinación
A26: 04.01 | B26: SECAP | C26: Informe | D26: Solicitar y entregar informe mensual | E26: EDDY VELEZ | F26: 15 | G26: 20 | H26: 51136 | I26: 46298 | J26: 46300 | K26: Cerrado | L26: Alta | M26: 1 | N26: =IF(I26="","",I26-CONFIGURACION!$B$8) -> -11 | O26: =IF(I26="","Sin fecha",IF(K26="Cerrado","Completado",IF(I26<CONFIGURACION!$B$8,"Vencido",IF(I26-CONFIGURACION!$B$8<=3,"Próximo","En plazo")))) -> Completado | P26: Fechas del cronograma de informes de agosto 2026 | Q26: Imagen: cronograma de informes
A27: 04.02 | B27: SECAP | C27: Abastecimiento | D27: Solicitar requerimientos de insumos | E27: EDDY VELEZ | F27: 1 | G27: 3 | H27: 46310 | I27: 46315 | K27: Pendiente | L27: Alta | M27: 0 | N27: =IF(I27="","",I27-CONFIGURACION!$B$8) -> 6 | O27: =IF(I27="","Sin fecha",IF(K27="Cerrado","Completado",IF(I27<CONFIGURACION!$B$8,"Vencido",IF(I27-CONFIGURACION!$B$8<=3,"Próximo","En plazo")))) -> En plazo | P27: Fechas del cronograma de abastecimiento de septiembre 2026 | Q27: Imagen: cronograma abastecimiento
A28: 04.03 | B28: SECAP | C28: Corte | D28: Preparar y entregar corte del día 5 | F28: 5 | G28: 5 | H28: =IF(F28="","",DATE(CONFIGURACION!$B$4,CONFIGURACION!$B$5,MIN(F28,DAY(CONFIGURACION!$B$7)))) -> 46300 | I28: =IF(G28="","",DATE(CONFIGURACION!$B$4,CONFIGURACION!$B$5,MIN(G28,DAY(CONFIGURACION!$B$7)))) -> 46300 | K28: Cerrado | L28: Alta | M28: 1 | N28: =IF(I28="","",I28-CONFIGURACION!$B$8) -> -9 | O28: =IF(I28="","Sin fecha",IF(K28="Cerrado","Completado",IF(I28<CONFIGURACION!$B$8,"Vencido",IF(I28-CONFIGURACION!$B$8<=3,"Próximo","En plazo")))) -> Completado | P28: Corte fijo mensual; confirmar responsable | Q28: Indicaciones de coordinación
A29: 04.04 | B29: SECAP | C29: Corte | D29: Preparar y entregar corte del día 10 | F29: 10 | G29: 10 | H29: =IF(F29="","",DATE(CONFIGURACION!$B$4,CONFIGURACION!$B$5,MIN(F29,DAY(CONFIGURACION!$B$7)))) -> 46305 | I29: =IF(G29="","",DATE(CONFIGURACION!$B$4,CONFIGURACION!$B$5,MIN(G29,DAY(CONFIGURACION!$B$7)))) -> 46305 | K29: Cerrado | L29: Alta | M29: 1 | N29: =IF(I29="","",I29-CONFIGURACION!$B$8) -> -4 | O29: =IF(I29="","Sin fecha",IF(K29="Cerrado","Completado",IF(I29<CONFIGURACION!$B$8,"Vencido",IF(I29-CONFIGURACION!$B$8<=3,"Próximo","En plazo")))) -> Completado | P29: Corte fijo mensual; confirmar responsable | Q29: Indicaciones de coordinación
A30: 04.05 | B30: SECAP | C30: Corte | D30: Preparar y entregar corte del día 20 | F30: 20 | G30: 20 | H30: =IF(F30="","",DATE(CONFIGURACION!$B$4,CONFIGURACION!$B$5,MIN(F30,DAY(CONFIGURACION!$B$7)))) -> 46315 | I30: =IF(G30="","",DATE(CONFIGURACION!$B$4,CONFIGURACION!$B$5,MIN(G30,DAY(CONFIGURACION!$B$7)))) -> 46315 | K30: Pendiente | L30: Alta | M30: 0 | N30: =IF(I30="","",I30-CONFIGURACION!$B$8) -> 6 | O30: =IF(I30="","Sin fecha",IF(K30="Cerrado","Completado",IF(I30<CONFIGURACION!$B$8,"Vencido",IF(I30-CONFIGURACION!$B$8<=3,"Próximo","En plazo")))) -> En plazo | P30: Corte fijo mensual; confirmar responsable | Q30: Indicaciones de coordinación
A31: 04.06 | B31: SECAP | C31: Corte | D31: Preparar y entregar corte del día 26 | F31: 26 | G31: 26 | H31: =IF(F31="","",DATE(CONFIGURACION!$B$4,CONFIGURACION!$B$5,MIN(F31,DAY(CONFIGURACION!$B$7)))) -> 46321 | I31: =IF(G31="","",DATE(CONFIGURACION!$B$4,CONFIGURACION!$B$5,MIN(G31,DAY(CONFIGURACION!$B$7)))) -> 46321 | K31: Pendiente | L31: Alta | M31: 0 | N31: =IF(I31="","",I31-CONFIGURACION!$B$8) -> 12 | O31: =IF(I31="","Sin fecha",IF(K31="Cerrado","Completado",IF(I31<CONFIGURACION!$B$8,"Vencido",IF(I31-CONFIGURACION!$B$8<=3,"Próximo","En plazo")))) -> En plazo | P31: Corte fijo mensual; confirmar responsable | Q31: Indicaciones de coordinación
A32: 04.07 | B32: SECAP | C32: Corte | D32: Preparar y entregar corte del día 30 | F32: 30 | G32: 30 | H32: =IF(F32="","",DATE(CONFIGURACION!$B$4,CONFIGURACION!$B$5,MIN(F32,DAY(CONFIGURACION!$B$7)))) -> 46325 | I32: =IF(G32="","",DATE(CONFIGURACION!$B$4,CONFIGURACION!$B$5,MIN(G32,DAY(CONFIGURACION!$B$7)))) -> 46325 | K32: Pendiente | L32: Alta | M32: 0 | N32: =IF(I32="","",I32-CONFIGURACION!$B$8) -> 16 | O32: =IF(I32="","Sin fecha",IF(K32="Cerrado","Completado",IF(I32<CONFIGURACION!$B$8,"Vencido",IF(I32-CONFIGURACION!$B$8<=3,"Próximo","En plazo")))) -> En plazo | P32: Corte fijo mensual; confirmar responsable | Q32: Indicaciones de coordinación
A33: 05.01 | B33: SENAE | C33: Informe | D33: Solicitar y entregar informe mensual | E33: EDDY VELEZ | F33: 9 | G33: 11 | H33: 46299 | I33: 46301 | J33: 46303 | K33: Cerrado | L33: Alta | M33: 1 | N33: =IF(I33="","",I33-CONFIGURACION!$B$8) -> -8 | O33: =IF(I33="","Sin fecha",IF(K33="Cerrado","Completado",IF(I33<CONFIGURACION!$B$8,"Vencido",IF(I33-CONFIGURACION!$B$8<=3,"Próximo","En plazo")))) -> Completado | P33: Fechas del cronograma de informes de agosto 2026 | Q33: Imagen: cronograma de informes
A34: 05.02 | B34: SENAE | C34: Abastecimiento | D34: Solicitar requerimientos de insumos | E34: EDDY VELEZ | F34: 4 | G34: 6 | H34: 46304 | I34: 46306 | K34: Pendiente | L34: Alta | M34: 0 | N34: =IF(I34="","",I34-CONFIGURACION!$B$8) -> -3 | O34: =IF(I34="","Sin fecha",IF(K34="Cerrado","Completado",IF(I34<CONFIGURACION!$B$8,"Vencido",IF(I34-CONFIGURACION!$B$8<=3,"Próximo","En plazo")))) -> Vencido | P34: Fechas del cronograma de abastecimiento de septiembre 2026 | Q34: Imagen: cronograma abastecimiento
A35: 05.03 | B35: SENAE | C35: Corte | D35: Preparar y entregar corte del día 5 | F35: 5 | G35: 5 | H35: =IF(F35="","",DATE(CONFIGURACION!$B$4,CONFIGURACION!$B$5,MIN(F35,DAY(CONFIGURACION!$B$7)))) -> 46300 | I35: =IF(G35="","",DATE(CONFIGURACION!$B$4,CONFIGURACION!$B$5,MIN(G35,DAY(CONFIGURACION!$B$7)))) -> 46300 | K35: Cerrado | L35: Alta | M35: 1 | N35: =IF(I35="","",I35-CONFIGURACION!$B$8) -> -9 | O35: =IF(I35="","Sin fecha",IF(K35="Cerrado","Completado",IF(I35<CONFIGURACION!$B$8,"Vencido",IF(I35-CONFIGURACION!$B$8<=3,"Próximo","En plazo")))) -> Completado | P35: Corte fijo mensual; confirmar responsable | Q35: Indicaciones de coordinación
A36: 05.04 | B36: SENAE | C36: Corte | D36: Preparar y entregar corte del día 10 | F36: 10 | G36: 10 | H36: =IF(F36="","",DATE(CONFIGURACION!$B$4,CONFIGURACION!$B$5,MIN(F36,DAY(CONFIGURACION!$B$7)))) -> 46305 | I36: =IF(G36="","",DATE(CONFIGURACION!$B$4,CONFIGURACION!$B$5,MIN(G36,DAY(CONFIGURACION!$B$7)))) -> 46305 | K36: Cerrado | L36: Alta | M36: 1 | N36: =IF(I36="","",I36-CONFIGURACION!$B$8) -> -4 | O36: =IF(I36="","Sin fecha",IF(K36="Cerrado","Completado",IF(I36<CONFIGURACION!$B$8,"Vencido",IF(I36-CONFIGURACION!$B$8<=3,"Próximo","En plazo")))) -> Completado | P36: Corte fijo mensual; confirmar responsable | Q36: Indicaciones de coordinación
A37: 05.05 | B37: SENAE | C37: Corte | D37: Preparar y entregar corte del día 20 | F37: 20 | G37: 20 | H37: =IF(F37="","",DATE(CONFIGURACION!$B$4,CONFIGURACION!$B$5,MIN(F37,DAY(CONFIGURACION!$B$7)))) -> 46315 | I37: =IF(G37="","",DATE(CONFIGURACION!$B$4,CONFIGURACION!$B$5,MIN(G37,DAY(CONFIGURACION!$B$7)))) -> 46315 | K37: Pendiente | L37: Alta | M37: 0 | N37: =IF(I37="","",I37-CONFIGURACION!$B$8) -> 6 | O37: =IF(I37="","Sin fecha",IF(K37="Cerrado","Completado",IF(I37<CONFIGURACION!$B$8,"Vencido",IF(I37-CONFIGURACION!$B$8<=3,"Próximo","En plazo")))) -> En plazo | P37: Corte fijo mensual; confirmar responsable | Q37: Indicaciones de coordinación
A38: 05.06 | B38: SENAE | C38: Corte | D38: Preparar y entregar corte del día 26 | F38: 26 | G38: 26 | H38: =IF(F38="","",DATE(CONFIGURACION!$B$4,CONFIGURACION!$B$5,MIN(F38,DAY(CONFIGURACION!$B$7)))) -> 46321 | I38: =IF(G38="","",DATE(CONFIGURACION!$B$4,CONFIGURACION!$B$5,MIN(G38,DAY(CONFIGURACION!$B$7)))) -> 46321 | K38: Pendiente | L38: Alta | M38: 0 | N38: =IF(I38="","",I38-CONFIGURACION!$B$8) -> 12 | O38: =IF(I38="","Sin fecha",IF(K38="Cerrado","Completado",IF(I38<CONFIGURACION!$B$8,"Vencido",IF(I38-CONFIGURACION!$B$8<=3,"Próximo","En plazo")))) -> En plazo | P38: Corte fijo mensual; confirmar responsable | Q38: Indicaciones de coordinación
A39: 05.07 | B39: SENAE | C39: Corte | D39: Preparar y entregar corte del día 30 | F39: 30 | G39: 30 | H39: =IF(F39="","",DATE(CONFIGURACION!$B$4,CONFIGURACION!$B$5,MIN(F39,DAY(CONFIGURACION!$B$7)))) -> 46325 | I39: =IF(G39="","",DATE(CONFIGURACION!$B$4,CONFIGURACION!$B$5,MIN(G39,DAY(CONFIGURACION!$B$7)))) -> 46325 | K39: Pendiente | L39: Alta | M39: 0 | N39: =IF(I39="","",I39-CONFIGURACION!$B$8) -> 16 | O39: =IF(I39="","Sin fecha",IF(K39="Cerrado","Completado",IF(I39<CONFIGURACION!$B$8,"Vencido",IF(I39-CONFIGURACION!$B$8<=3,"Próximo","En plazo")))) -> En plazo | P39: Corte fijo mensual; confirmar responsable | Q39: Indicaciones de coordinación
A40: 06.01 | B40: CELEC - ORIENTE | C40: Informe | D40: Solicitar y entregar informe mensual | H40: =IF(F40="","",DATE(CONFIGURACION!$B$4,CONFIGURACION!$B$5,MIN(F40,DAY(CONFIGURACION!$B$7)))) | I40: =IF(G40="","",DATE(CONFIGURACION!$B$4,CONFIGURACION!$B$5,MIN(G40,DAY(CONFIGURACION!$B$7)))) | K40: Pendiente | L40: Alta | M40: 0 | N40: =IF(I40="","",I40-CONFIGURACION!$B$8) | O40: =IF(I40="","Sin fecha",IF(K40="Cerrado","Completado",IF(I40<CONFIGURACION!$B$8,"Vencido",IF(I40-CONFIGURACION!$B$8<=3,"Próximo","En plazo")))) -> Sin fecha | P40: PENDIENTE: completar fechas y responsable | Q40: Por definir
A41: 06.02 | B41: CELEC - ORIENTE | C41: Abastecimiento | D41: Solicitar requerimientos de insumos | H41: =IF(F41="","",DATE(CONFIGURACION!$B$4,CONFIGURACION!$B$5,MIN(F41,DAY(CONFIGURACION!$B$7)))) | I41: =IF(G41="","",DATE(CONFIGURACION!$B$4,CONFIGURACION!$B$5,MIN(G41,DAY(CONFIGURACION!$B$7)))) | K41: Pendiente | L41: Alta | M41: 0 | N41: =IF(I41="","",I41-CONFIGURACION!$B$8) | O41: =IF(I41="","Sin fecha",IF(K41="Cerrado","Completado",IF(I41<CONFIGURACION!$B$8,"Vencido",IF(I41-CONFIGURACION!$B$8<=3,"Próximo","En plazo")))) -> Sin fecha | P41: PENDIENTE: completar fechas y responsable | Q41: Por definir
A42: 06.03 | B42: CELEC - ORIENTE | C42: Corte | D42: Preparar y entregar corte del día 5 | F42: 5 | G42: 5 | H42: =IF(F42="","",DATE(CONFIGURACION!$B$4,CONFIGURACION!$B$5,MIN(F42,DAY(CONFIGURACION!$B$7)))) -> 46300 | I42: =IF(G42="","",DATE(CONFIGURACION!$B$4,CONFIGURACION!$B$5,MIN(G42,DAY(CONFIGURACION!$B$7)))) -> 46300 | K42: Cerrado | L42: Alta | M42: 1 | N42: =IF(I42="","",I42-CONFIGURACION!$B$8) -> -9 | O42: =IF(I42="","Sin fecha",IF(K42="Cerrado","Completado",IF(I42<CONFIGURACION!$B$8,"Vencido",IF(I42-CONFIGURACION!$B$8<=3,"Próximo","En plazo")))) -> Completado | P42: Corte fijo mensual; confirmar responsable | Q42: Indicaciones de coordinación
...

Sheet EDT
A1: EDT | ENTREGABLES, PLAZOS Y SEGUIMIENTO
A4: Código EDT | B4: Proyecto | C4: Paquete de trabajo | D4: Entregable | E4: Responsable | F4: Inicio | G4: Fecha límite | H4: Días disponibles | I4: Estado | J4: Avance | K4: Alerta | L4: Dependencia / nota
A5: =IF(ACTIVIDADES!A5="","",ACTIVIDADES!A5) -> 01.01 | B5: =IF(ACTIVIDADES!B5="","",ACTIVIDADES!B5) -> CDJ GUAYAQUIL | C5: =IF(ACTIVIDADES!C5="","",ACTIVIDADES!C5) -> Informe | D5: =IF(ACTIVIDADES!D5="","",ACTIVIDADES!D5) -> Solicitar y entregar informe mensual | E5: =IF(ACTIVIDADES!E5="","",ACTIVIDADES!E5) -> LUIS HARO | F5: =IF(ACTIVIDADES!H5="","",ACTIVIDADES!H5) -> 46302 | G5: =IF(ACTIVIDADES!I5="","",ACTIVIDADES!I5) -> 46305 | H5: =IF(OR(F5="",G5=""),"",G5-F5+1) -> 4 | I5: =ACTIVIDADES!K5 -> Pendiente | J5: =ACTIVIDADES!M5 -> 0 | K5: =ACTIVIDADES!O5 -> Vencido | L5: =ACTIVIDADES!P5 -> Fechas del cronograma de informes de agosto 2026
A6: =IF(ACTIVIDADES!A6="","",ACTIVIDADES!A6) -> 01.02 | B6: =IF(ACTIVIDADES!B6="","",ACTIVIDADES!B6) -> CDJ GUAYAQUIL | C6: =IF(ACTIVIDADES!C6="","",ACTIVIDADES!C6) -> Abastecimiento | D6: =IF(ACTIVIDADES!D6="","",ACTIVIDADES!D6) -> Solicitar requerimientos de insumos | E6: =IF(ACTIVIDADES!E6="","",ACTIVIDADES!E6) -> EDDY VELEZ | F6: =IF(ACTIVIDADES!H6="","",ACTIVIDADES!H6) -> 46294 | G6: =IF(ACTIVIDADES!I6="","",ACTIVIDADES!I6) -> 46298 | H6: =IF(OR(F6="",G6=""),"",G6-F6+1) -> 5 | I6: =ACTIVIDADES!K6 -> Cerrado | J6: =ACTIVIDADES!M6 -> 1 | K6: =ACTIVIDADES!O6 -> Completado | L6: =ACTIVIDADES!P6 -> Fechas del cronograma de abastecimiento de septiembre 2026
A7: =IF(ACTIVIDADES!A7="","",ACTIVIDADES!A7) -> 01.03 | B7: =IF(ACTIVIDADES!B7="","",ACTIVIDADES!B7) -> CDJ GUAYAQUIL | C7: =IF(ACTIVIDADES!C7="","",ACTIVIDADES!C7) -> Corte | D7: =IF(ACTIVIDADES!D7="","",ACTIVIDADES!D7) -> Preparar y entregar corte del día 5 | E7: =IF(ACTIVIDADES!E7="","",ACTIVIDADES!E7) | F7: =IF(ACTIVIDADES!H7="","",ACTIVIDADES!H7) -> 46300 | G7: =IF(ACTIVIDADES!I7="","",ACTIVIDADES!I7) -> 46300 | H7: =IF(OR(F7="",G7=""),"",G7-F7+1) -> 1 | I7: =ACTIVIDADES!K7 -> Cerrado | J7: =ACTIVIDADES!M7 -> 1 | K7: =ACTIVIDADES!O7 -> Completado | L7: =ACTIVIDADES!P7 -> Corte fijo mensual; confirmar responsable
A8: =IF(ACTIVIDADES!A8="","",ACTIVIDADES!A8) -> 01.04 | B8: =IF(ACTIVIDADES!B8="","",ACTIVIDADES!B8) -> CDJ GUAYAQUIL | C8: =IF(ACTIVIDADES!C8="","",ACTIVIDADES!C8) -> Corte | D8: =IF(ACTIVIDADES!D8="","",ACTIVIDADES!D8) -> Preparar y entregar corte del día 10 | E8: =IF(ACTIVIDADES!E8="","",ACTIVIDADES!E8) | F8: =IF(ACTIVIDADES!H8="","",ACTIVIDADES!H8) -> 46305 | G8: =IF(ACTIVIDADES!I8="","",ACTIVIDADES!I8) -> 46305 | H8: =IF(OR(F8="",G8=""),"",G8-F8+1) -> 1 | I8: =ACTIVIDADES!K8 -> Cerrado | J8: =ACTIVIDADES!M8 -> 1 | K8: =ACTIVIDADES!O8 -> Completado | L8: =ACTIVIDADES!P8 -> Corte fijo mensual; confirmar responsable
A9: =IF(ACTIVIDADES!A9="","",ACTIVIDADES!A9) -> 01.05 | B9: =IF(ACTIVIDADES!B9="","",ACTIVIDADES!B9) -> CDJ GUAYAQUIL | C9: =IF(ACTIVIDADES!C9="","",ACTIVIDADES!C9) -> Corte | D9: =IF(ACTIVIDADES!D9="","",ACTIVIDADES!D9) -> Preparar y entregar corte del día 20 | E9: =IF(ACTIVIDADES!E9="","",ACTIVIDADES!E9) | F9: =IF(ACTIVIDADES!H9="","",ACTIVIDADES!H9) -> 46315 | G9: =IF(ACTIVIDADES!I9="","",ACTIVIDADES!I9) -> 46315 | H9: =IF(OR(F9="",G9=""),"",G9-F9+1) -> 1 | I9: =ACTIVIDADES!K9 -> Pendiente | J9: =ACTIVIDADES!M9 -> 0 | K9: =ACTIVIDADES!O9 -> En plazo | L9: =ACTIVIDADES!P9 -> Corte fijo mensual; confirmar responsable
A10: =IF(ACTIVIDADES!A10="","",ACTIVIDADES!A10) -> 01.06 | B10: =IF(ACTIVIDADES!B10="","",ACTIVIDADES!B10) -> CDJ GUAYAQUIL | C10: =IF(ACTIVIDADES!C10="","",ACTIVIDADES!C10) -> Corte | D10: =IF(ACTIVIDADES!D10="","",ACTIVIDADES!D10) -> Preparar y entregar corte del día 26 | E10: =IF(ACTIVIDADES!E10="","",ACTIVIDADES!E10) | F10: =IF(ACTIVIDADES!H10="","",ACTIVIDADES!H10) -> 46321 | G10: =IF(ACTIVIDADES!I10="","",ACTIVIDADES!I10) -> 46321 | H10: =IF(OR(F10="",G10=""),"",G10-F10+1) -> 1 | I10: =ACTIVIDADES!K10 -> Pendiente | J10: =ACTIVIDADES!M10 -> 0 | K10: =ACTIVIDADES!O10 -> En plazo | L10: =ACTIVIDADES!P10 -> Corte fijo mensual; confirmar responsable
A11: =IF(ACTIVIDADES!A11="","",ACTIVIDADES!A11) -> 01.07 | B11: =IF(ACTIVIDADES!B11="","",ACTIVIDADES!B11) -> CDJ GUAYAQUIL | C11: =IF(ACTIVIDADES!C11="","",ACTIVIDADES!C11) -> Corte | D11: =IF(ACTIVIDADES!D11="","",ACTIVIDADES!D11) -> Preparar y entregar corte del día 30 | E11: =IF(ACTIVIDADES!E11="","",ACTIVIDADES!E11) | F11: =IF(ACTIVIDADES!H11="","",ACTIVIDADES!H11) -> 46325 | G11: =IF(ACTIVIDADES!I11="","",ACTIVIDADES!I11) -> 46325 | H11: =IF(OR(F11="",G11=""),"",G11-F11+1) -> 1 | I11: =ACTIVIDADES!K11 -> Pendiente | J11: =ACTIVIDADES!M11 -> 0 | K11: =ACTIVIDADES!O11 -> En plazo | L11: =ACTIVIDADES!P11 -> Corte fijo mensual; confirmar responsable
A12: =IF(ACTIVIDADES!A12="","",ACTIVIDADES!A12) -> 02.01 | B12: =IF(ACTIVIDADES!B12="","",ACTIVIDADES!B12) -> CDJ CANTONES | C12: =IF(ACTIVIDADES!C12="","",ACTIVIDADES!C12) -> Informe | D12: =IF(ACTIVIDADES!D12="","",ACTIVIDADES!D12) -> Solicitar y entregar informe mensual | E12: =IF(ACTIVIDADES!E12="","",ACTIVIDADES!E12) -> LUIS HARO | F12: =IF(ACTIVIDADES!H12="","",ACTIVIDADES!H12) -> 46302 | G12: =IF(ACTIVIDADES!I12="","",ACTIVIDADES!I12) -> 46305 | H12: =IF(OR(F12="",G12=""),"",G12-F12+1) -> 4 | I12: =ACTIVIDADES!K12 -> Cerrado | J12: =ACTIVIDADES!M12 -> 1 | K12: =ACTIVIDADES!O12 -> Completado | L12: =ACTIVIDADES!P12 -> Fechas del cronograma de informes de agosto 2026
A13: =IF(ACTIVIDADES!A13="","",ACTIVIDADES!A13) -> 02.02 | B13: =IF(ACTIVIDADES!B13="","",ACTIVIDADES!B13) -> CDJ CANTONES | C13: =IF(ACTIVIDADES!C13="","",ACTIVIDADES!C13) -> Abastecimiento | D13: =IF(ACTIVIDADES!D13="","",ACTIVIDADES!D13) -> Solicitar requerimientos de insumos | E13: =IF(ACTIVIDADES!E13="","",ACTIVIDADES!E13) -> LUIS HARO | F13: =IF(ACTIVIDADES!H13="","",ACTIVIDADES!H13) -> 46324 | G13: =IF(ACTIVIDADES!I13="","",ACTIVIDADES!I13) -> 46329 | H13: =IF(OR(F13="",G13=""),"",G13-F13+1) -> 6 | I13: =ACTIVIDADES!K13 -> Pendiente | J13: =ACTIVIDADES!M13 -> 0 | K13: =ACTIVIDADES!O13 -> En plazo | L13: =ACTIVIDADES!P13 -> Fechas del cronograma de abastecimiento de septiembre 2026
A14: =IF(ACTIVIDADES!A14="","",ACTIVIDADES!A14) -> 02.03 | B14: =IF(ACTIVIDADES!B14="","",ACTIVIDADES!B14) -> CDJ CANTONES | C14: =IF(ACTIVIDADES!C14="","",ACTIVIDADES!C14) -> Corte | D14: =IF(ACTIVIDADES!D14="","",ACTIVIDADES!D14) -> Preparar y entregar corte del día 5 | E14: =IF(ACTIVIDADES!E14="","",ACTIVIDADES!E14) | F14: =IF(ACTIVIDADES!H14="","",ACTIVIDADES!H14) -> 46300 | G14: =IF(ACTIVIDADES!I14="","",ACTIVIDADES!I14) -> 46300 | H14: =IF(OR(F14="",G14=""),"",G14-F14+1) -> 1 | I14: =ACTIVIDADES!K14 -> Cerrado | J14: =ACTIVIDADES!M14 -> 1 | K14: =ACTIVIDADES!O14 -> Completado | L14: =ACTIVIDADES!P14 -> Corte fijo mensual; confirmar responsable
A15: =IF(ACTIVIDADES!A15="","",ACTIVIDADES!A15) -> 02.04 | B15: =IF(ACTIVIDADES!B15="","",ACTIVIDADES!B15) -> CDJ CANTONES | C15: =IF(ACTIVIDADES!C15="","",ACTIVIDADES!C15) -> Corte | D15: =IF(ACTIVIDADES!D15="","",ACTIVIDADES!D15) -> Preparar y entregar corte del día 10 | E15: =IF(ACTIVIDADES!E15="","",ACTIVIDADES!E15) | F15: =IF(ACTIVIDADES!H15="","",ACTIVIDADES!H15) -> 46305 | G15: =IF(ACTIVIDADES!I15="","",ACTIVIDADES!I15) -> 46305 | H15: =IF(OR(F15="",G15=""),"",G15-F15+1) -> 1 | I15: =ACTIVIDADES!K15 -> Cerrado | J15: =ACTIVIDADES!M15 -> 1 | K15: =ACTIVIDADES!O15 -> Completado | L15: =ACTIVIDADES!P15 -> Corte fijo mensual; confirmar responsable
A16: =IF(ACTIVIDADES!A16="","",ACTIVIDADES!A16) -> 02.05 | B16: =IF(ACTIVIDADES!B16="","",ACTIVIDADES!B16) -> CDJ CANTONES | C16: =IF(ACTIVIDADES!C16="","",ACTIVIDADES!C16) -> Corte | D16: =IF(ACTIVIDADES!D16="","",ACTIVIDADES!D16) -> Preparar y entregar corte del día 20 | E16: =IF(ACTIVIDADES!E16="","",ACTIVIDADES!E16) | F16: =IF(ACTIVIDADES!H16="","",ACTIVIDADES!H16) -> 46315 | G16: =IF(ACTIVIDADES!I16="","",ACTIVIDADES!I16) -> 46315 | H16: =IF(OR(F16="",G16=""),"",G16-F16+1) -> 1 | I16: =ACTIVIDADES!K16 -> Pendiente | J16: =ACTIVIDADES!M16 -> 0 | K16: =ACTIVIDADES!O16 -> En plazo | L16: =ACTIVIDADES!P16 -> Corte fijo mensual; confirmar responsable
... A84: =IF(ACTIVIDADES!A84="","",ACTIVIDADES!A84) -> EX.24 | B84: =IF(ACTIVIDADES!B84="","",ACTIVIDADES!B84) | C84: =IF(ACTIVIDADES!C84="","",ACTIVIDADES!C84) -> No planificada | D84: =IF(ACTIVIDADES!D84="","",ACTIVIDADES!D84) | E84: =IF(ACTIVIDADES!E84="","",ACTIVIDADES!E84) | F84: =IF(ACTIVIDADES!H84="","",ACTIVIDADES!H84) | G84: =IF(ACTIVIDADES!I84="","",ACTIVIDADES!I84) | H84: =IF(OR(F84="",G84=""),"",G84-F84+1) | I84: =ACTIVIDADES!K84 -> Pendiente | J84: =ACTIVIDADES!M84 -> 0 | K84: =ACTIVIDADES!O84 -> Sin fecha | L84: =ACTIVIDADES!P84 -> Registro disponible para nuevas actividades

Sheet CALENDARIO
A1: CALENDARIO MENSUAL | FECHAS DE ENTREGA
A4: Código EDT | B4: Proyecto | C4: Tipo | D4: Actividad / entregable | E4: =IF(1<=DAY(CONFIGURACION!$B$7),DATE(CONFIGURACION!$B$4,CONFIGURACION!$B$5,1),"") -> 46296 | F4: =IF(2<=DAY(CONFIGURACION!$B$7),DATE(CONFIGURACION!$B$4,CONFIGURACION!$B$5,2),"") -> 46297 | G4: =IF(3<=DAY(CONFIGURACION!$B$7),DATE(CONFIGURACION!$B$4,CONFIGURACION!$B$5,3),"") -> 46298 | H4: =IF(4<=DAY(CONFIGURACION!$B$7),DATE(CONFIGURACION!$B$4,CONFIGURACION!$B$5,4),"") -> 46299 | I4: =IF(5<=DAY(CONFIGURACION!$B$7),DATE(CONFIGURACION!$B$4,CONFIGURACION!$B$5,5),"") -> 46300 | J4: =IF(6<=DAY(CONFIGURACION!$B$7),DATE(CONFIGURACION!$B$4,CONFIGURACION!$B$5,6),"") -> 46301 | K4: =IF(7<=DAY(CONFIGURACION!$B$7),DATE(CONFIGURACION!$B$4,CONFIGURACION!$B$5,7),"") -> 46302 | L4: =IF(8<=DAY(CONFIGURACION!$B$7),DATE(CONFIGURACION!$B$4,CONFIGURACION!$B$5,8),"") -> 46303 | M4: =IF(9<=DAY(CONFIGURACION!$B$7),DATE(CONFIGURACION!$B$4,CONFIGURACION!$B$5,9),"") -> 46304 | N4: =IF(10<=DAY(CONFIGURACION!$B$7),DATE(CONFIGURACION!$B$4,CONFIGURACION!$B$5,10),"") -> 46305 | O4: =IF(11<=DAY(CONFIGURACION!$B$7),DATE(CONFIGURACION!$B$4,CONFIGURACION!$B$5,11),"") -> 46306 | P4: =IF(12<=DAY(CONFIGURACION!$B$7),DATE(CONFIGURACION!$B$4,CONFIGURACION!$B$5,12),"") -> 46307 | Q4: =IF(13<=DAY(CONFIGURACION!$B$7),DATE(CONFIGURACION!$B$4,CONFIGURACION!$B$5,13),"") -> 46308 | R4: =IF(14<=DAY(CONFIGURACION!$B$7),DATE(CONFIGURACION!$B$4,CONFIGURACION!$B$5,14),"") -> 46309 | S4: =IF(15<=DAY(CONFIGURACION!$B$7),DATE(CONFIGURACION!$B$4,CONFIGURACION!$B$5,15),"") -> 46310 | T4: =IF(16<=DAY(CONFIGURACION!$B$7),DATE(CONFIGURACION!$B$4,CONFIGURACION!$B$5,16),"") -> 46311 | U4: =IF(17<=DAY(CONFIGURACION!$B$7),DATE(CONFIGURACION!$B$4,CONFIGURACION!$B$5,17),"") -> 46312 | V4: =IF(18<=DAY(CONFIGURACION!$B$7),DATE(CONFIGURACION!$B$4,CONFIGURACION!$B$5,18),"") -> 46313 | W4: =IF(19<=DAY(CONFIGURACION!$B$7),DATE(CONFIGURACION!$B$4,CONFIGURACION!$B$5,19),"") -> 46314 | X4: =IF(20<=DAY(CONFIGURACION!$B$7),DATE(CONFIGURACION!$B$4,CONFIGURACION!$B$5,20),"") -> 46315 | Y4: =IF(21<=DAY(CONFIGURACION!$B$7),DATE(CONFIGURACION!$B$4,CONFIGURACION!$B$5,21),"") -> 46316 | Z4: =IF(22<=DAY(CONFIGURACION!$B$7),DATE(CONFIGURACION!$B$4,CONFIGURACION!$B$5,22),"") -> 46317 | AA4: =IF(23<=DAY(CONFIGURACION!$B$7),DATE(CONFIGURACION!$B$4,CONFIGURACION!$B$5,23),"") -> 46318 | AB4: =IF(24<=DAY(CONFIGURACION!$B$7),DATE(CONFIGURACION!$B$4,CONFIGURACION!$B$5,24),"") -> 46319 | AC4: =IF(25<=DAY(CONFIGURACION!$B$7),DATE(CONFIGURACION!$B$4,CONFIGURACION!$B$5,25),"") -> 46320 | AD4: =IF(26<=DAY(CONFIGURACION!$B$7),DATE(CONFIGURACION!$B$4,CONFIGURACION!$B$5,26),"") -> 46321 | AE4: =IF(27<=DAY(CONFIGURACION!$B$7),DATE(CONFIGURACION!$B$4,CONFIGURACION!$B$5,27),"") -> 46322 | AF4: =IF(28<=DAY(CONFIGURACION!$B$7),DATE(CONFIGURACION!$B$4,CONFIGURACION!$B$5,28),"") -> 46323 | AG4: =IF(29<=DAY(CONFIGURACION!$B$7),DATE(CONFIGURACION!$B$4,CONFIGURACION!$B$5,29),"") -> 46324 | AH4: =IF(30<=DAY(CONFIGURACION!$B$7),DATE(CONFIGURACION!$B$4,CONFIGURACION!$B$5,30),"") -> 46325 | AI4: =IF(31<=DAY(CONFIGURACION!$B$7),DATE(CONFIGURACION!$B$4,CONFIGURACION!$B$5,31),"") -> 46326 | AJ4: Estado
A5: =IF(ACTIVIDADES!A5="","",ACTIVIDADES!A5) -> 01.01 | B5: =IF(ACTIVIDADES!B5="","",ACTIVIDADES!B5) -> CDJ GUAYAQUIL | C5: =IF(ACTIVIDADES!C5="","",ACTIVIDADES!C5) -> Informe | D5: =IF(ACTIVIDADES!D5="","",ACTIVIDADES!D5) -> Solicitar y entregar informe mensual | E5: =IF(OR(ACTIVIDADES!$I5="",D$4=""),"",IF(ACTIVIDADES!$I5=D$4,"●",IF(AND(ACTIVIDADES!$H5<=D$4,ACTIVIDADES!$I5>=D$4),"·",""))) | F5: =IF(OR(ACTIVIDADES!$I5="",E$4=""),"",IF(ACTIVIDADES!$I5=E$4,"●",IF(AND(ACTIVIDADES!$H5<=E$4,ACTIVIDADES!$I5>=E$4),"·",""))) | G5: =IF(OR(ACTIVIDADES!$I5="",F$4=""),"",IF(ACTIVIDADES!$I5=F$4,"●",IF(AND(ACTIVIDADES!$H5<=F$4,ACTIVIDADES!$I5>=F$4),"·",""))) | H5: =IF(OR(ACTIVIDADES!$I5="",G$4=""),"",IF(ACTIVIDADES!$I5=G$4,"●",IF(AND(ACTIVIDADES!$H5<=G$4,ACTIVIDADES!$I5>=G$4),"·",""))) | I5: =IF(OR(ACTIVIDADES!$I5="",H$4=""),"",IF(ACTIVIDADES!$I5=H$4,"●",IF(AND(ACTIVIDADES!$H5<=H$4,ACTIVIDADES!$I5>=H$4),"·",""))) | J5: =IF(OR(ACTIVIDADES!$I5="",I$4=""),"",IF(ACTIVIDADES!$I5=I$4,"●",IF(AND(ACTIVIDADES!$H5<=I$4,ACTIVIDADES!$I5>=I$4),"·",""))) | K5: =IF(OR(ACTIVIDADES!$I5="",J$4=""),"",IF(ACTIVIDADES!$I5=J$4,"●",IF(AND(ACTIVIDADES!$H5<=J$4,ACTIVIDADES!$I5>=J$4),"·",""))) | L5: =IF(OR(ACTIVIDADES!$I5="",K$4=""),"",IF(ACTIVIDADES!$I5=K$4,"●",IF(AND(ACTIVIDADES!$H5<=K$4,ACTIVIDADES!$I5>=K$4),"·",""))) -> · | ... AI5: =IF(OR(ACTIVIDADES!$I5="",AH$4=""),"",IF(ACTIVIDADES!$I5=AH$4,"●",IF(AND(ACTIVIDADES!$H5<=AH$4,ACTIVIDADES!$I5>=AH$4),"·",""))) | AJ5: =IF(ACTIVIDADES!K5="","",ACTIVIDADES!K5) -> Pendiente
A6: =IF(ACTIVIDADES!A6="","",ACTIVIDADES!A6) -> 01.02 | B6: =IF(ACTIVIDADES!B6="","",ACTIVIDADES!B6) -> CDJ GUAYAQUIL | C6: =IF(ACTIVIDADES!C6="","",ACTIVIDADES!C6) -> Abastecimiento | D6: =IF(ACTIVIDADES!D6="","",ACTIVIDADES!D6) -> Solicitar requerimientos de insumos | E6: =IF(OR(ACTIVIDADES!$I6="",D$4=""),"",IF(ACTIVIDADES!$I6=D$4,"●",IF(AND(ACTIVIDADES!$H6<=D$4,ACTIVIDADES!$I6>=D$4),"·",""))) | F6: =IF(OR(ACTIVIDADES!$I6="",E$4=""),"",IF(ACTIVIDADES!$I6=E$4,"●",IF(AND(ACTIVIDADES!$H6<=E$4,ACTIVIDADES!$I6>=E$4),"·",""))) -> · | G6: =IF(OR(ACTIVIDADES!$I6="",F$4=""),"",IF(ACTIVIDADES!$I6=F$4,"●",IF(AND(ACTIVIDADES!$H6<=F$4,ACTIVIDADES!$I6>=F$4),"·",""))) -> · | H6: =IF(OR(ACTIVIDADES!$I6="",G$4=""),"",IF(ACTIVIDADES!$I6=G$4,"●",IF(AND(ACTIVIDADES!$H6<=G$4,ACTIVIDADES!$I6>=G$4),"·",""))) -> ● | I6: =IF(OR(ACTIVIDADES!$I6="",H$4=""),"",IF(ACTIVIDADES!$I6=H$4,"●",IF(AND(ACTIVIDADES!$H6<=H$4,ACTIVIDADES!$I6>=H$4),"·",""))) | J6: =IF(OR(ACTIVIDADES!$I6="",I$4=""),"",IF(ACTIVIDADES!$I6=I$4,"●",IF(AND(ACTIVIDADES!$H6<=I$4,ACTIVIDADES!$I6>=I$4),"·",""))) | K6: =IF(OR(ACTIVIDADES!$I6="",J$4=""),"",IF(ACTIVIDADES!$I6=J$4,"●",IF(AND(ACTIVIDADES!$H6<=J$4,ACTIVIDADES!$I6>=J$4),"·",""))) | L6: =IF(OR(ACTIVIDADES!$I6="",K$4=""),"",IF(ACTIVIDADES!$I6=K$4,"●",IF(AND(ACTIVIDADES!$H6<=K$4,ACTIVIDADES!$I6>=K$4),"·",""))) | ... AI6: =IF(OR(ACTIVIDADES!$I6="",AH$4=""),"",IF(ACTIVIDADES!$I6=AH$4,"●",IF(AND(ACTIVIDADES!$H6<=AH$4,ACTIVIDADES!$I6>=AH$4),"·",""))) | AJ6: =IF(ACTIVIDADES!K6="","",ACTIVIDADES!K6) -> Cerrado
A7: =IF(ACTIVIDADES!A7="","",ACTIVIDADES!A7) -> 01.03 | B7: =IF(ACTIVIDADES!B7="","",ACTIVIDADES!B7) -> CDJ GUAYAQUIL | C7: =IF(ACTIVIDADES!C7="","",ACTIVIDADES!C7) -> Corte | D7: =IF(ACTIVIDADES!D7="","",ACTIVIDADES!D7) -> Preparar y entregar corte del día 5 | E7: =IF(OR(ACTIVIDADES!$I7="",D$4=""),"",IF(ACTIVIDADES!$I7=D$4,"●",IF(AND(ACTIVIDADES!$H7<=D$4,ACTIVIDADES!$I7>=D$4),"·",""))) | F7: =IF(OR(ACTIVIDADES!$I7="",E$4=""),"",IF(ACTIVIDADES!$I7=E$4,"●",IF(AND(ACTIVIDADES!$H7<=E$4,ACTIVIDADES!$I7>=E$4),"·",""))) | G7: =IF(OR(ACTIVIDADES!$I7="",F$4=""),"",IF(ACTIVIDADES!$I7=F$4,"●",IF(AND(ACTIVIDADES!$H7<=F$4,ACTIVIDADES!$I7>=F$4),"·",""))) | H7: =IF(OR(ACTIVIDADES!$I7="",G$4=""),"",IF(ACTIVIDADES!$I7=G$4,"●",IF(AND(ACTIVIDADES!$H7<=G$4,ACTIVIDADES!$I7>=G$4),"·",""))) | I7: =IF(OR(ACTIVIDADES!$I7="",H$4=""),"",IF(ACTIVIDADES!$I7=H$4,"●",IF(AND(ACTIVIDADES!$H7<=H$4,ACTIVIDADES!$I7>=H$4),"·",""))) | J7: =IF(OR(ACTIVIDADES!$I7="",I$4=""),"",IF(ACTIVIDADES!$I7=I$4,"●",IF(AND(ACTIVIDADES!$H7<=I$4,ACTIVIDADES!$I7>=I$4),"·",""))) -> ● | K7: =IF(OR(ACTIVIDADES!$I7="",J$4=""),"",IF(ACTIVIDADES!$I7=J$4,"●",IF(AND(ACTIVIDADES!$H7<=J$4,ACTIVIDADES!$I7>=J$4),"·",""))) | L7: =IF(OR(ACTIVIDADES!$I7="",K$4=""),"",IF(ACTIVIDADES!$I7=K$4,"●",IF(AND(ACTIVIDADES!$H7<=K$4,ACTIVIDADES!$I7>=K$4),"·",""))) | ... AI7: =IF(OR(ACTIVIDADES!$I7="",AH$4=""),"",IF(ACTIVIDADES!$I7=AH$4,"●",IF(AND(ACTIVIDADES!$H7<=AH$4,ACTIVIDADES!$I7>=AH$4),"·",""))) | AJ7: =IF(ACTIVIDADES!K7="","",ACTIVIDADES!K7) -> Cerrado
A8: =IF(ACTIVIDADES!A8="","",ACTIVIDADES!A8) -> 01.04 | B8: =IF(ACTIVIDADES!B8="","",ACTIVIDADES!B8) -> CDJ GUAYAQUIL | C8: =IF(ACTIVIDADES!C8="","",ACTIVIDADES!C8) -> Corte | D8: =IF(ACTIVIDADES!D8="","",ACTIVIDADES!D8) -> Preparar y entregar corte del día 10 | E8: =IF(OR(ACTIVIDADES!$I8="",D$4=""),"",IF(ACTIVIDADES!$I8=D$4,"●",IF(AND(ACTIVIDADES!$H8<=D$4,ACTIVIDADES!$I8>=D$4),"·",""))) | F8: =IF(OR(ACTIVIDADES!$I8="",E$4=""),"",IF(ACTIVIDADES!$I8=E$4,"●",IF(AND(ACTIVIDADES!$H8<=E$4,ACTIVIDADES!$I8>=E$4),"·",""))) | G8: =IF(OR(ACTIVIDADES!$I8="",F$4=""),"",IF(ACTIVIDADES!$I8=F$4,"●",IF(AND(ACTIVIDADES!$H8<=F$4,ACTIVIDADES!$I8>=F$4),"·",""))) | H8: =IF(OR(ACTIVIDADES!$I8="",G$4=""),"",IF(ACTIVIDADES!$I8=G$4,"●",IF(AND(ACTIVIDADES!$H8<=G$4,ACTIVIDADES!$I8>=G$4),"·",""))) | I8: =IF(OR(ACTIVIDADES!$I8="",H$4=""),"",IF(ACTIVIDADES!$I8=H$4,"●",IF(AND(ACTIVIDADES!$H8<=H$4,ACTIVIDADES!$I8>=H$4),"·",""))) | J8: =IF(OR(ACTIVIDADES!$I8="",I$4=""),"",IF(ACTIVIDADES!$I8=I$4,"●",IF(AND(ACTIVIDADES!$H8<=I$4,ACTIVIDADES!$I8>=I$4),"·",""))) | K8: =IF(OR(ACTIVIDADES!$I8="",J$4=""),"",IF(ACTIVIDADES!$I8=J$4,"●",IF(AND(ACTIVIDADES!$H8<=J$4,ACTIVIDADES!$I8>=J$4),"·",""))) | L8: =IF(OR(ACTIVIDADES!$I8="",K$4=""),"",IF(ACTIVIDADES!$I8=K$4,"●",IF(AND(ACTIVIDADES!$H8<=K$4,ACTIVIDADES!$I8>=K$4),"·",""))) | ... AI8: =IF(OR(ACTIVIDADES!$I8="",AH$4=""),"",IF(ACTIVIDADES!$I8=AH$4,"●",IF(AND(ACTIVIDADES!$H8<=AH$4,ACTIVIDADES!$I8>=AH$4),"·",""))) | AJ8: =IF(ACTIVIDADES!K8="","",ACTIVIDADES!K8) -> Cerrado
A9: =IF(ACTIVIDADES!A9="","",ACTIVIDADES!A9) -> 01.05 | B9: =IF(ACTIVIDADES!B9="","",ACTIVIDADES!B9) -> CDJ GUAYAQUIL | C9: =IF(ACTIVIDADES!C9="","",ACTIVIDADES!C9) -> Corte | D9: =IF(ACTIVIDADES!D9="","",ACTIVIDADES!D9) -> Preparar y entregar corte del día 20 | E9: =IF(OR(ACTIVIDADES!$I9="",D$4=""),"",IF(ACTIVIDADES!$I9=D$4,"●",IF(AND(ACTIVIDADES!$H9<=D$4,ACTIVIDADES!$I9>=D$4),"·",""))) | F9: =IF(OR(ACTIVIDADES!$I9="",E$4=""),"",IF(ACTIVIDADES!$I9=E$4,"●",IF(AND(ACTIVIDADES!$H9<=E$4,ACTIVIDADES!$I9>=E$4),"·",""))) | G9: =IF(OR(ACTIVIDADES!$I9="",F$4=""),"",IF(ACTIVIDADES!$I9=F$4,"●",IF(AND(ACTIVIDADES!$H9<=F$4,ACTIVIDADES!$I9>=F$4),"·",""))) | H9: =IF(OR(ACTIVIDADES!$I9="",G$4=""),"",IF(ACTIVIDADES!$I9=G$4,"●",IF(AND(ACTIVIDADES!$H9<=G$4,ACTIVIDADES!$I9>=G$4),"·",""))) | I9: =IF(OR(ACTIVIDADES!$I9="",H$4=""),"",IF(ACTIVIDADES!$I9=H$4,"●",IF(AND(ACTIVIDADES!$H9<=H$4,ACTIVIDADES!$I9>=H$4),"·",""))) | J9: =IF(OR(ACTIVIDADES!$I9="",I$4=""),"",IF(ACTIVIDADES!$I9=I$4,"●",IF(AND(ACTIVIDADES!$H9<=I$4,ACTIVIDADES!$I9>=I$4),"·",""))) | K9: =IF(OR(ACTIVIDADES!$I9="",J$4=""),"",IF(ACTIVIDADES!$I9=J$4,"●",IF(AND(ACTIVIDADES!$H9<=J$4,ACTIVIDADES!$I9>=J$4),"·",""))) | L9: =IF(OR(ACTIVIDADES!$I9="",K$4=""),"",IF(ACTIVIDADES!$I9=K$4,"●",IF(AND(ACTIVIDADES!$H9<=K$4,ACTIVIDADES!$I9>=K$4),"·",""))) | ... AI9: =IF(OR(ACTIVIDADES!$I9="",AH$4=""),"",IF(ACTIVIDADES!$I9=AH$4,"●",IF(AND(ACTIVIDADES!$H9<=AH$4,ACTIVIDADES!$I9>=AH$4),"·",""))) | AJ9: =IF(ACTIVIDADES!K9="","",ACTIVIDADES!K9) -> Pendiente
A10: =IF(ACTIVIDADES!A10="","",ACTIVIDADES!A10) -> 01.06 | B10: =IF(ACTIVIDADES!B10="","",ACTIVIDADES!B10) -> CDJ GUAYAQUIL | C10: =IF(ACTIVIDADES!C10="","",ACTIVIDADES!C10) -> Corte | D10: =IF(ACTIVIDADES!D10="","",ACTIVIDADES!D10) -> Preparar y entregar corte del día 26 | E10: =IF(OR(ACTIVIDADES!$I10="",D$4=""),"",IF(ACTIVIDADES!$I10=D$4,"●",IF(AND(ACTIVIDADES!$H10<=D$4,ACTIVIDADES!$I10>=D$4),"·",""))) | F10: =IF(OR(ACTIVIDADES!$I10="",E$4=""),"",IF(ACTIVIDADES!$I10=E$4,"●",IF(AND(ACTIVIDADES!$H10<=E$4,ACTIVIDADES!$I10>=E$4),"·",""))) | G10: =IF(OR(ACTIVIDADES!$I10="",F$4=""),"",IF(ACTIVIDADES!$I10=F$4,"●",IF(AND(ACTIVIDADES!$H10<=F$4,ACTIVIDADES!$I10>=F$4),"·",""))) | H10: =IF(OR(ACTIVIDADES!$I10="",G$4=""),"",IF(ACTIVIDADES!$I10=G$4,"●",IF(AND(ACTIVIDADES!$H10<=G$4,ACTIVIDADES!$I10>=G$4),"·",""))) | I10: =IF(OR(ACTIVIDADES!$I10="",H$4=""),"",IF(ACTIVIDADES!$I10=H$4,"●",IF(AND(ACTIVIDADES!$H10<=H$4,ACTIVIDADES!$I10>=H$4),"·",""))) | J10: =IF(OR(ACTIVIDADES!$I10="",I$4=""),"",IF(ACTIVIDADES!$I10=I$4,"●",IF(AND(ACTIVIDADES!$H10<=I$4,ACTIVIDADES!$I10>=I$4),"·",""))) | K10: =IF(OR(ACTIVIDADES!$I10="",J$4=""),"",IF(ACTIVIDADES!$I10=J$4,"●",IF(AND(ACTIVIDADES!$H10<=J$4,ACTIVIDADES!$I10>=J$4),"·",""))) | L10: =IF(OR(ACTIVIDADES!$I10="",K$4=""),"",IF(ACTIVIDADES!$I10=K$4,"●",IF(AND(ACTIVIDADES!$H10<=K$4,ACTIVIDADES!$I10>=K$4),"·",""))) | ... AI10: =IF(OR(ACTIVIDADES!$I10="",AH$4=""),"",IF(ACTIVIDADES!$I10=AH$4,"●",IF(AND(ACTIVIDADES!$H10<=AH$4,ACTIVIDADES!$I10>=AH$4),"·",""))) | AJ10: =IF(ACTIVIDADES!K10="","",ACTIVIDADES!K10) -> Pendiente
A11: =IF(ACTIVIDADES!A11="","",ACTIVIDADES!A11) -> 01.07 | B11: =IF(ACTIVIDADES!B11="","",ACTIVIDADES!B11) -> CDJ GUAYAQUIL | C11: =IF(ACTIVIDADES!C11="","",ACTIVIDADES!C11) -> Corte | D11: =IF(ACTIVIDADES!D11="","",ACTIVIDADES!D11) -> Preparar y entregar corte del día 30 | E11: =IF(OR(ACTIVIDADES!$I11="",D$4=""),"",IF(ACTIVIDADES!$I11=D$4,"●",IF(AND(ACTIVIDADES!$H11<=D$4,ACTIVIDADES!$I11>=D$4),"·",""))) | F11: =IF(OR(ACTIVIDADES!$I11="",E$4=""),"",IF(ACTIVIDADES!$I11=E$4,"●",IF(AND(ACTIVIDADES!$H11<=E$4,ACTIVIDADES!$I11>=E$4),"·",""))) | G11: =IF(OR(ACTIVIDADES!$I11="",F$4=""),"",IF(ACTIVIDADES!$I11=F$4,"●",IF(AND(ACTIVIDADES!$H11<=F$4,ACTIVIDADES!$I11>=F$4),"·",""))) | H11: =IF(OR(ACTIVIDADES!$I11="",G$4=""),"",IF(ACTIVIDADES!$I11=G$4,"●",IF(AND(ACTIVIDADES!$H11<=G$4,ACTIVIDADES!$I11>=G$4),"·",""))) | I11: =IF(OR(ACTIVIDADES!$I11="",H$4=""),"",IF(ACTIVIDADES!$I11=H$4,"●",IF(AND(ACTIVIDADES!$H11<=H$4,ACTIVIDADES!$I11>=H$4),"·",""))) | J11: =IF(OR(ACTIVIDADES!$I11="",I$4=""),"",IF(ACTIVIDADES!$I11=I$4,"●",IF(AND(ACTIVIDADES!$H11<=I$4,ACTIVIDADES!$I11>=I$4),"·",""))) | K11: =IF(OR(ACTIVIDADES!$I11="",J$4=""),"",IF(ACTIVIDADES!$I11=J$4,"●",IF(AND(ACTIVIDADES!$H11<=J$4,ACTIVIDADES!$I11>=J$4),"·",""))) | L11: =IF(OR(ACTIVIDADES!$I11="",K$4=""),"",IF(ACTIVIDADES!$I11=K$4,"●",IF(AND(ACTIVIDADES!$H11<=K$4,ACTIVIDADES!$I11>=K$4),"·",""))) | ... AI11: =IF(OR(ACTIVIDADES!$I11="",AH$4=""),"",IF(ACTIVIDADES!$I11=AH$4,"●",IF(AND(ACTIVIDADES!$H11<=AH$4,ACTIVIDADES!$I11>=AH$4),"·",""))) -> ● | AJ11: =IF(ACTIVIDADES!K11="","",ACTIVIDADES!K11) -> Pendiente
A12: =IF(ACTIVIDADES!A12="","",ACTIVIDADES!A12) -> 02.01 | B12: =IF(ACTIVIDADES!B12="","",ACTIVIDADES!B12) -> CDJ CANTONES | C12: =IF(ACTIVIDADES!C12="","",ACTIVIDADES!C12) -> Informe | D12: =IF(ACTIVIDADES!D12="","",ACTIVIDADES!D12) -> Solicitar y entregar informe mensual | E12: =IF(OR(ACTIVIDADES!$I12="",D$4=""),"",IF(ACTIVIDADES!$I12=D$4,"●",IF(AND(ACTIVIDADES!$H12<=D$4,ACTIVIDADES!$I12>=D$4),"·",""))) | F12: =IF(OR(ACTIVIDADES!$I12="",E$4=""),"",IF(ACTIVIDADES!$I12=E$4,"●",IF(AND(ACTIVIDADES!$H12<=E$4,ACTIVIDADES!$I12>=E$4),"·",""))) | G12: =IF(OR(ACTIVIDADES!$I12="",F$4=""),"",IF(ACTIVIDADES!$I12=F$4,"●",IF(AND(ACTIVIDADES!$H12<=F$4,ACTIVIDADES!$I12>=F$4),"·",""))) | H12: =IF(OR(ACTIVIDADES!$I12="",G$4=""),"",IF(ACTIVIDADES!$I12=G$4,"●",IF(AND(ACTIVIDADES!$H12<=G$4,ACTIVIDADES!$I12>=G$4),"·",""))) | I12: =IF(OR(ACTIVIDADES!$I12="",H$4=""),"",IF(ACTIVIDADES!$I12=H$4,"●",IF(AND(ACTIVIDADES!$H12<=H$4,ACTIVIDADES!$I12>=H$4),"·",""))) | J12: =IF(OR(ACTIVIDADES!$I12="",I$4=""),"",IF(ACTIVIDADES!$I12=I$4,"●",IF(AND(ACTIVIDADES!$H12<=I$4,ACTIVIDADES!$I12>=I$4),"·",""))) | K12: =IF(OR(ACTIVIDADES!$I12="",J$4=""),"",IF(ACTIVIDADES!$I12=J$4,"●",IF(AND(ACTIVIDADES!$H12<=J$4,ACTIVIDADES!$I12>=J$4),"·",""))) | L12: =IF(OR(ACTIVIDADES!$I12="",K$4=""),"",IF(ACTIVIDADES!$I12=K$4,"●",IF(AND(ACTIVIDADES!$H12<=K$4,ACTIVIDADES!$I12>=K$4),"·",""))) -> · | ... AI12: =IF(OR(ACTIVIDADES!$I12="",AH$4=""),"",IF(ACTIVIDADES!$I12=AH$4,"●",IF(AND(ACTIVIDADES!$H12<=AH$4,ACTIVIDADES!$I12>=AH$4),"·",""))) | AJ12: =IF(ACTIVIDADES!K12="","",ACTIVIDADES!K12) -> Cerrado
A13: =IF(ACTIVIDADES!A13="","",ACTIVIDADES!A13) -> 02.02 | B13: =IF(ACTIVIDADES!B13="","",ACTIVIDADES!B13) -> CDJ CANTONES | C13: =IF(ACTIVIDADES!C13="","",ACTIVIDADES!C13) -> Abastecimiento | D13: =IF(ACTIVIDADES!D13="","",ACTIVIDADES!D13) -> Solicitar requerimientos de insumos | E13: =IF(OR(ACTIVIDADES!$I13="",D$4=""),"",IF(ACTIVIDADES!$I13=D$4,"●",IF(AND(ACTIVIDADES!$H13<=D$4,ACTIVIDADES!$I13>=D$4),"·",""))) | F13: =IF(OR(ACTIVIDADES!$I13="",E$4=""),"",IF(ACTIVIDADES!$I13=E$4,"●",IF(AND(ACTIVIDADES!$H13<=E$4,ACTIVIDADES!$I13>=E$4),"·",""))) | G13: =IF(OR(ACTIVIDADES!$I13="",F$4=""),"",IF(ACTIVIDADES!$I13=F$4,"●",IF(AND(ACTIVIDADES!$H13<=F$4,ACTIVIDADES!$I13>=F$4),"·",""))) | H13: =IF(OR(ACTIVIDADES!$I13="",G$4=""),"",IF(ACTIVIDADES!$I13=G$4,"●",IF(AND(ACTIVIDADES!$H13<=G$4,ACTIVIDADES!$I13>=G$4),"·",""))) | I13: =IF(OR(ACTIVIDADES!$I13="",H$4=""),"",IF(ACTIVIDADES!$I13=H$4,"●",IF(AND(ACTIVIDADES!$H13<=H$4,ACTIVIDADES!$I13>=H$4),"·",""))) | J13: =IF(OR(ACTIVIDADES!$I13="",I$4=""),"",IF(ACTIVIDADES!$I13=I$4,"●",IF(AND(ACTIVIDADES!$H13<=I$4,ACTIVIDADES!$I13>=I$4),"·",""))) | K13: =IF(OR(ACTIVIDADES!$I13="",J$4=""),"",IF(ACTIVIDADES!$I13=J$4,"●",IF(AND(ACTIVIDADES!$H13<=J$4,ACTIVIDADES!$I13>=J$4),"·",""))) | L13: =IF(OR(ACTIVIDADES!$I13="",K$4=""),"",IF(ACTIVIDADES!$I13=K$4,"●",IF(AND(ACTIVIDADES!$H13<=K$4,ACTIVIDADES!$I13>=K$4),"·",""))) | ... AI13: =IF(OR(ACTIVIDADES!$I13="",AH$4=""),"",IF(ACTIVIDADES!$I13=AH$4,"●",IF(AND(ACTIVIDADES!$H13<=AH$4,ACTIVIDADES!$I13>=AH$4),"·",""))) -> · | AJ13: =IF(ACTIVIDADES!K13="","",ACTIVIDADES!K13) -> Pendiente
A14: =IF(ACTIVIDADES!A14="","",ACTIVIDADES!A14) -> 02.03 | B14: =IF(ACTIVIDADES!B14="","",ACTIVIDADES!B14) -> CDJ CANTONES | C14: =IF(ACTIVIDADES!C14="","",ACTIVIDADES!C14) -> Corte | D14: =IF(ACTIVIDADES!D14="","",ACTIVIDADES!D14) -> Preparar y entregar corte del día 5 | E14: =IF(OR(ACTIVIDADES!$I14="",D$4=""),"",IF(ACTIVIDADES!$I14=D$4,"●",IF(AND(ACTIVIDADES!$H14<=D$4,ACTIVIDADES!$I14>=D$4),"·",""))) | F14: =IF(OR(ACTIVIDADES!$I14="",E$4=""),"",IF(ACTIVIDADES!$I14=E$4,"●",IF(AND(ACTIVIDADES!$H14<=E$4,ACTIVIDADES!$I14>=E$4),"·",""))) | G14: =IF(OR(ACTIVIDADES!$I14="",F$4=""),"",IF(ACTIVIDADES!$I14=F$4,"●",IF(AND(ACTIVIDADES!$H14<=F$4,ACTIVIDADES!$I14>=F$4),"·",""))) | H14: =IF(OR(ACTIVIDADES!$I14="",G$4=""),"",IF(ACTIVIDADES!$I14=G$4,"●",IF(AND(ACTIVIDADES!$H14<=G$4,ACTIVIDADES!$I14>=G$4),"·",""))) | I14: =IF(OR(ACTIVIDADES!$I14="",H$4=""),"",IF(ACTIVIDADES!$I14=H$4,"●",IF(AND(ACTIVIDADES!$H14<=H$4,ACTIVIDADES!$I14>=H$4),"·",""))) | J14: =IF(OR(ACTIVIDADES!$I14="",I$4=""),"",IF(ACTIVIDADES!$I14=I$4,"●",IF(AND(ACTIVIDADES!$H14<=I$4,ACTIVIDADES!$I14>=I$4),"·",""))) -> ● | K14: =IF(OR(ACTIVIDADES!$I14="",J$4=""),"",IF(ACTIVIDADES!$I14=J$4,"●",IF(AND(ACTIVIDADES!$H14<=J$4,ACTIVIDADES!$I14>=J$4),"·",""))) | L14: =IF(OR(ACTIVIDADES!$I14="",K$4=""),"",IF(ACTIVIDADES!$I14=K$4,"●",IF(AND(ACTIVIDADES!$H14<=K$4,ACTIVIDADES!$I14>=K$4),"·",""))) | ... AI14: =IF(OR(ACTIVIDADES!$I14="",AH$4=""),"",IF(ACTIVIDADES!$I14=AH$4,"●",IF(AND(ACTIVIDADES!$H14<=AH$4,ACTIVIDADES!$I14>=AH$4),"·",""))) | AJ14: =IF(ACTIVIDADES!K14="","",ACTIVIDADES!K14) -> Cerrado
A15: =IF(ACTIVIDADES!A15="","",ACTIVIDADES!A15) -> 02.04 | B15: =IF(ACTIVIDADES!B15="","",ACTIVIDADES!B15) -> CDJ CANTONES | C15: =IF(ACTIVIDADES!C15="","",ACTIVIDADES!C15) -> Corte | D15: =IF(ACTIVIDADES!D15="","",ACTIVIDADES!D15) -> Preparar y entregar corte del día 10 | E15: =IF(OR(ACTIVIDADES!$I15="",D$4=""),"",IF(ACTIVIDADES!$I15=D$4,"●",IF(AND(ACTIVIDADES!$H15<=D$4,ACTIVIDADES!$I15>=D$4),"·",""))) | F15: =IF(OR(ACTIVIDADES!$I15="",E$4=""),"",IF(ACTIVIDADES!$I15=E$4,"●",IF(AND(ACTIVIDADES!$H15<=E$4,ACTIVIDADES!$I15>=E$4),"·",""))) | G15: =IF(OR(ACTIVIDADES!$I15="",F$4=""),"",IF(ACTIVIDADES!$I15=F$4,"●",IF(AND(ACTIVIDADES!$H15<=F$4,ACTIVIDADES!$I15>=F$4),"·",""))) | H15: =IF(OR(ACTIVIDADES!$I15="",G$4=""),"",IF(ACTIVIDADES!$I15=G$4,"●",IF(AND(ACTIVIDADES!$H15<=G$4,ACTIVIDADES!$I15>=G$4),"·",""))) | I15: =IF(OR(ACTIVIDADES!$I15="",H$4=""),"",IF(ACTIVIDADES!$I15=H$4,"●",IF(AND(ACTIVIDADES!$H15<=H$4,ACTIVIDADES!$I15>=H$4),"·",""))) | J15: =IF(OR(ACTIVIDADES!$I15="",I$4=""),"",IF(ACTIVIDADES!$I15=I$4,"●",IF(AND(ACTIVIDADES!$H15<=I$4,ACTIVIDADES!$I15>=I$4),"·",""))) | K15: =IF(OR(ACTIVIDADES!$I15="",J$4=""),"",IF(ACTIVIDADES!$I15=J$4,"●",IF(AND(ACTIVIDADES!$H15<=J$4,ACTIVIDADES!$I15>=J$4),"·",""))) | L15: =IF(OR(ACTIVIDADES!$I15="",K$4=""),"",IF(ACTIVIDADES!$I15=K$4,"●",IF(AND(ACTIVIDADES!$H15<=K$4,ACTIVIDADES!$I15>=K$4),"·",""))) | ... AI15: =IF(OR(ACTIVIDADES!$I15="",AH$4=""),"",IF(ACTIVIDADES!$I15=AH$4,"●",IF(AND(ACTIVIDADES!$H15<=AH$4,ACTIVIDADES!$I15>=AH$4),"·",""))) | AJ15: =IF(ACTIVIDADES!K15="","",ACTIVIDADES!K15) -> Cerrado
A16: =IF(ACTIVIDADES!A16="","",ACTIVIDADES!A16) -> 02.05 | B16: =IF(ACTIVIDADES!B16="","",ACTIVIDADES!B16) -> CDJ CANTONES | C16: =IF(ACTIVIDADES!C16="","",ACTIVIDADES!C16) -> Corte | D16: =IF(ACTIVIDADES!D16="","",ACTIVIDADES!D16) -> Preparar y entregar corte del día 20 | E16: =IF(OR(ACTIVIDADES!$I16="",D$4=""),"",IF(ACTIVIDADES!$I16=D$4,"●",IF(AND(ACTIVIDADES!$H16<=D$4,ACTIVIDADES!$I16>=D$4),"·",""))) | F16: =IF(OR(ACTIVIDADES!$I16="",E$4=""),"",IF(ACTIVIDADES!$I16=E$4,"●",IF(AND(ACTIVIDADES!$H16<=E$4,ACTIVIDADES!$I16>=E$4),"·",""))) | G16: =IF(OR(ACTIVIDADES!$I16="",F$4=""),"",IF(ACTIVIDADES!$I16=F$4,"●",IF(AND(ACTIVIDADES!$H16<=F$4,ACTIVIDADES!$I16>=F$4),"·",""))) | H16: =IF(OR(ACTIVIDADES!$I16="",G$4=""),"",IF(ACTIVIDADES!$I16=G$4,"●",IF(AND(ACTIVIDADES!$H16<=G$4,ACTIVIDADES!$I16>=G$4),"·",""))) | I16: =IF(OR(ACTIVIDADES!$I16="",H$4=""),"",IF(ACTIVIDADES!$I16=H$4,"●",IF(AND(ACTIVIDADES!$H16<=H$4,ACTIVIDADES!$I16>=H$4),"·",""))) | J16: =IF(OR(ACTIVIDADES!$I16="",I$4=""),"",IF(ACTIVIDADES!$I16=I$4,"●",IF(AND(ACTIVIDADES!$H16<=I$4,ACTIVIDADES!$I16>=I$4),"·",""))) | K16: =IF(OR(ACTIVIDADES!$I16="",J$4=""),"",IF(ACTIVIDADES!$I16=J$4,"●",IF(AND(ACTIVIDADES!$H16<=J$4,ACTIVIDADES!$I16>=J$4),"·",""))) | L16: =IF(OR(ACTIVIDADES!$I16="",K$4=""),"",IF(ACTIVIDADES!$I16=K$4,"●",IF(AND(ACTIVIDADES!$H16<=K$4,ACTIVIDADES!$I16>=K$4),"·",""))) | ... AI16: =IF(OR(ACTIVIDADES!$I16="",AH$4=""),"",IF(ACTIVIDADES!$I16=AH$4,"●",IF(AND(ACTIVIDADES!$H16<=AH$4,ACTIVIDADES!$I16>=AH$4),"·",""))) | AJ16: =IF(ACTIVIDADES!K16="","",ACTIVIDADES!K16) -> Pendiente
... A84: =IF(ACTIVIDADES!A84="","",ACTIVIDADES!A84) -> EX.24 | B84: =IF(ACTIVIDADES!B84="","",ACTIVIDADES!B84) | C84: =IF(ACTIVIDADES!C84="","",ACTIVIDADES!C84) -> No planificada | D84: =IF(ACTIVIDADES!D84="","",ACTIVIDADES!D84) | E84: =IF(OR(ACTIVIDADES!$I84="",D$4=""),"",IF(ACTIVIDADES!$I84=D$4,"●",IF(AND(ACTIVIDADES!$H84<=D$4,ACTIVIDADES!$I84>=D$4),"·",""))) | F84: =IF(OR(ACTIVIDADES!$I84="",E$4=""),"",IF(ACTIVIDADES!$I84=E$4,"●",IF(AND(ACTIVIDADES!$H84<=E$4,ACTIVIDADES!$I84>=E$4),"·",""))) | G84: =IF(OR(ACTIVIDADES!$I84="",F$4=""),"",IF(ACTIVIDADES!$I84=F$4,"●",IF(AND(ACTIVIDADES!$H84<=F$4,ACTIVIDADES!$I84>=F$4),"·",""))) | H84: =IF(OR(ACTIVIDADES!$I84="",G$4=""),"",IF(ACTIVIDADES!$I84=G$4,"●",IF(AND(ACTIVIDADES!$H84<=G$4,ACTIVIDADES!$I84>=G$4),"·",""))) | I84: =IF(OR(ACTIVIDADES!$I84="",H$4=""),"",IF(ACTIVIDADES!$I84=H$4,"●",IF(AND(ACTIVIDADES!$H84<=H$4,ACTIVIDADES!$I84>=H$4),"·",""))) | J84: =IF(OR(ACTIVIDADES!$I84="",I$4=""),"",IF(ACTIVIDADES!$I84=I$4,"●",IF(AND(ACTIVIDADES!$H84<=I$4,ACTIVIDADES!$I84>=I$4),"·",""))) | K84: =IF(OR(ACTIVIDADES!$I84="",J$4=""),"",IF(ACTIVIDADES!$I84=J$4,"●",IF(AND(ACTIVIDADES!$H84<=J$4,ACTIVIDADES!$I84>=J$4),"·",""))) | L84: =IF(OR(ACTIVIDADES!$I84="",K$4=""),"",IF(ACTIVIDADES!$I84=K$4,"●",IF(AND(ACTIVIDADES!$H84<=K$4,ACTIVIDADES!$I84>=K$4),"·",""))) | ... AI84: =IF(OR(ACTIVIDADES!$I84="",AH$4=""),"",IF(ACTIVIDADES!$I84=AH$4,"●",IF(AND(ACTIVIDADES!$H84<=AH$4,ACTIVIDADES!$I84>=AH$4),"·",""))) | AJ84: =IF(ACTIVIDADES!K84="","",ACTIVIDADES!K84) -> Pendiente

Sheet TABLERO
A1: TABLERO DE CONTROL | SUPERVISIÓN
A4: Indicador | B4: Cantidad | D4: Proyecto | E4: Informes | F4: Abastecimiento | G4: Cortes
A5: Actividades registradas | B5: =COUNTA(ACTIVIDADES!A5:A200) -> 80 | D5: CDJ GUAYAQUIL | E5: =COUNTIFS(ACTIVIDADES!$B$5:$B$200,D5,ACTIVIDADES!$C$5:$C$200,"Informe") -> 1 | F5: =COUNTIFS(ACTIVIDADES!$B$5:$B$200,D5,ACTIVIDADES!$C$5:$C$200,"Abastecimiento") -> 1 | G5: =COUNTIFS(ACTIVIDADES!$B$5:$B$200,D5,ACTIVIDADES!$C$5:$C$200,"Corte") -> 5
A6: Pendientes | B6: =COUNTIF(ACTIVIDADES!K5:K200,"Pendiente") -> 59 | D6: CDJ CANTONES | E6: =COUNTIFS(ACTIVIDADES!$B$5:$B$200,D6,ACTIVIDADES!$C$5:$C$200,"Informe") -> 1 | F6: =COUNTIFS(ACTIVIDADES!$B$5:$B$200,D6,ACTIVIDADES!$C$5:$C$200,"Abastecimiento") -> 1 | G6: =COUNTIFS(ACTIVIDADES!$B$5:$B$200,D6,ACTIVIDADES!$C$5:$C$200,"Corte") -> 5
A7: En proceso | B7: =COUNTIF(ACTIVIDADES!K5:K200,"En proceso") -> 0 | D7: HOSP. MERCED | E7: =COUNTIFS(ACTIVIDADES!$B$5:$B$200,D7,ACTIVIDADES!$C$5:$C$200,"Informe") -> 1 | F7: =COUNTIFS(ACTIVIDADES!$B$5:$B$200,D7,ACTIVIDADES!$C$5:$C$200,"Abastecimiento") -> 1 | G7: =COUNTIFS(ACTIVIDADES!$B$5:$B$200,D7,ACTIVIDADES!$C$5:$C$200,"Corte") -> 5
A8: Cerradas | B8: =COUNTIF(ACTIVIDADES!K5:K200,"Cerrado") -> 21 | D8: SECAP | E8: =COUNTIFS(ACTIVIDADES!$B$5:$B$200,D8,ACTIVIDADES!$C$5:$C$200,"Informe") -> 1 | F8: =COUNTIFS(ACTIVIDADES!$B$5:$B$200,D8,ACTIVIDADES!$C$5:$C$200,"Abastecimiento") -> 1 | G8: =COUNTIFS(ACTIVIDADES!$B$5:$B$200,D8,ACTIVIDADES!$C$5:$C$200,"Corte") -> 5
A9: Vencidas | B9: =COUNTIF(ACTIVIDADES!O5:O200,"Vencido") -> 3 | D9: SENAE | E9: =COUNTIFS(ACTIVIDADES!$B$5:$B$200,D9,ACTIVIDADES!$C$5:$C$200,"Informe") -> 1 | F9: =COUNTIFS(ACTIVIDADES!$B$5:$B$200,D9,ACTIVIDADES!$C$5:$C$200,"Abastecimiento") -> 1 | G9: =COUNTIFS(ACTIVIDADES!$B$5:$B$200,D9,ACTIVIDADES!$C$5:$C$200,"Corte") -> 5
A10: Próximas (3 días) | B10: =COUNTIF(ACTIVIDADES!O5:O200,"Próximo") -> 0 | D10: CELEC - ORIENTE | E10: =COUNTIFS(ACTIVIDADES!$B$5:$B$200,D10,ACTIVIDADES!$C$5:$C$200,"Informe") -> 1 | F10: =COUNTIFS(ACTIVIDADES!$B$5:$B$200,D10,ACTIVIDADES!$C$5:$C$200,"Abastecimiento") -> 1 | G10: =COUNTIFS(ACTIVIDADES!$B$5:$B$200,D10,ACTIVIDADES!$C$5:$C$200,"Corte") -> 5
A11: Sin fecha límite | B11: =COUNTIF(ACTIVIDADES!O5:O200,"Sin fecha") -> 28 | D11: CELEC - GUAYAQUIL | E11: =COUNTIFS(ACTIVIDADES!$B$5:$B$200,D11,ACTIVIDADES!$C$5:$C$200,"Informe") -> 1 | F11: =COUNTIFS(ACTIVIDADES!$B$5:$B$200,D11,ACTIVIDADES!$C$5:$C$200,"Abastecimiento") -> 1 | G11: =COUNTIFS(ACTIVIDADES!$B$5:$B$200,D11,ACTIVIDADES!$C$5:$C$200,"Corte") -> 5
D12: MSP | E12: =COUNTIFS(ACTIVIDADES!$B$5:$B$200,D12,ACTIVIDADES!$C$5:$C$200,"Informe") -> 1 | F12: =COUNTIFS(ACTIVIDADES!$B$5:$B$200,D12,ACTIVIDADES!$C$5:$C$200,"Abastecimiento") -> 1 | G12: =COUNTIFS(ACTIVIDADES!$B$5:$B$200,D12,ACTIVIDADES!$C$5:$C$200,"Corte") -> 5
A14: CRITERIOS DE CONTROL
